[2022-10-25 15:15:43,126] {taskinstance.py:1159} INFO - Dependencies all met for <TaskInstance: 1_init_once_seed_data.load_seed_data_once manual__2022-10-25T15:15:40.120369+00:00 [queued]>
[2022-10-25 15:15:43,151] {taskinstance.py:1159} INFO - Dependencies all met for <TaskInstance: 1_init_once_seed_data.load_seed_data_once manual__2022-10-25T15:15:40.120369+00:00 [queued]>
[2022-10-25 15:15:43,152] {taskinstance.py:1356} INFO - 
--------------------------------------------------------------------------------
[2022-10-25 15:15:43,153] {taskinstance.py:1357} INFO - Starting attempt 1 of 1
[2022-10-25 15:15:43,154] {taskinstance.py:1358} INFO - 
--------------------------------------------------------------------------------
[2022-10-25 15:15:43,194] {taskinstance.py:1377} INFO - Executing <Task(BashOperator): load_seed_data_once> on 2022-10-25 15:15:40.120369+00:00
[2022-10-25 15:15:43,202] {standard_task_runner.py:52} INFO - Started process 706 to run task
[2022-10-25 15:15:43,214] {standard_task_runner.py:79} INFO - Running: ['***', 'tasks', 'run', '1_init_once_seed_data', 'load_seed_data_once', 'manual__2022-10-25T15:15:40.120369+00:00', '--job-id', '151', '--raw', '--subdir', 'DAGS_FOLDER/init.py', '--cfg-path', '/tmp/tmp77w9k7mk', '--error-file', '/tmp/tmpjdw70z9k']
[2022-10-25 15:15:43,215] {standard_task_runner.py:80} INFO - Job 151: Subtask load_seed_data_once
[2022-10-25 15:15:43,503] {task_command.py:369} INFO - Running <TaskInstance: 1_init_once_seed_data.load_seed_data_once manual__2022-10-25T15:15:40.120369+00:00 [running]> on host 0508f368e846
[2022-10-25 15:15:44,767] {taskinstance.py:1571} INFO - Exporting the following env vars:
AIRFLOW_CTX_DAG_OWNER=***
AIRFLOW_CTX_DAG_ID=1_init_once_seed_data
AIRFLOW_CTX_TASK_ID=load_seed_data_once
AIRFLOW_CTX_EXECUTION_DATE=2022-10-25T15:15:40.120369+00:00
AIRFLOW_CTX_TRY_NUMBER=1
AIRFLOW_CTX_DAG_RUN_ID=manual__2022-10-25T15:15:40.120369+00:00
[2022-10-25 15:15:44,787] {subprocess.py:62} INFO - Tmp dir root location: 
 /tmp
[2022-10-25 15:15:44,805] {subprocess.py:74} INFO - Running command: ['bash', '-c', 'cd /dbt_project && dbt seed --profiles-dir .']
[2022-10-25 15:15:44,924] {subprocess.py:85} INFO - Output:
[2022-10-25 15:15:44,930] {subprocess.py:92} INFO - bash: line 1: cd: /dbt_project: No such file or directory
[2022-10-25 15:15:44,947] {subprocess.py:96} INFO - Command exited with return code 1
[2022-10-25 15:15:45,039] {taskinstance.py:1889} ERROR - Task failed with exception
Traceback (most recent call last):
  File "/home/airflow/.local/lib/python3.7/site-packages/airflow/operators/bash.py", line 195, in execute
    f'Bash command failed. The command returned a non-zero exit code {result.exit_code}.'
airflow.exceptions.AirflowException: Bash command failed. The command returned a non-zero exit code 1.
[2022-10-25 15:15:45,070] {taskinstance.py:1400} INFO - Marking task as FAILED. dag_id=1_init_once_seed_data, task_id=load_seed_data_once, execution_date=20221025T151540, start_date=20221025T151543, end_date=20221025T151545
[2022-10-25 15:15:45,242] {standard_task_runner.py:97} ERROR - Failed to execute job 151 for task load_seed_data_once (Bash command failed. The command returned a non-zero exit code 1.; 706)
[2022-10-25 15:15:45,297] {local_task_job.py:156} INFO - Task exited with return code 1
[2022-10-25 15:15:45,542] {local_task_job.py:273} INFO - 0 downstream tasks scheduled from follow-on schedule check
