[2022-10-25 15:08:52,472] {taskinstance.py:1159} INFO - Dependencies all met for <TaskInstance: 1_init_once_seed_data.load_seed_data_once manual__2022-10-25T15:08:45.637429+00:00 [queued]>
[2022-10-25 15:08:52,534] {taskinstance.py:1159} INFO - Dependencies all met for <TaskInstance: 1_init_once_seed_data.load_seed_data_once manual__2022-10-25T15:08:45.637429+00:00 [queued]>
[2022-10-25 15:08:52,535] {taskinstance.py:1356} INFO - 
--------------------------------------------------------------------------------
[2022-10-25 15:08:52,535] {taskinstance.py:1357} INFO - Starting attempt 1 of 1
[2022-10-25 15:08:52,536] {taskinstance.py:1358} INFO - 
--------------------------------------------------------------------------------
[2022-10-25 15:08:52,651] {taskinstance.py:1377} INFO - Executing <Task(BashOperator): load_seed_data_once> on 2022-10-25 15:08:45.637429+00:00
[2022-10-25 15:08:52,680] {standard_task_runner.py:52} INFO - Started process 386 to run task
[2022-10-25 15:08:52,722] {standard_task_runner.py:79} INFO - Running: ['***', 'tasks', 'run', '1_init_once_seed_data', 'load_seed_data_once', 'manual__2022-10-25T15:08:45.637429+00:00', '--job-id', '149', '--raw', '--subdir', 'DAGS_FOLDER/init.py', '--cfg-path', '/tmp/tmp0qw2_opn', '--error-file', '/tmp/tmpbz_s09su']
[2022-10-25 15:08:52,724] {standard_task_runner.py:80} INFO - Job 149: Subtask load_seed_data_once
[2022-10-25 15:08:53,019] {task_command.py:369} INFO - Running <TaskInstance: 1_init_once_seed_data.load_seed_data_once manual__2022-10-25T15:08:45.637429+00:00 [running]> on host 0508f368e846
[2022-10-25 15:08:53,421] {taskinstance.py:1571} INFO - Exporting the following env vars:
AIRFLOW_CTX_DAG_OWNER=***
AIRFLOW_CTX_DAG_ID=1_init_once_seed_data
AIRFLOW_CTX_TASK_ID=load_seed_data_once
AIRFLOW_CTX_EXECUTION_DATE=2022-10-25T15:08:45.637429+00:00
AIRFLOW_CTX_TRY_NUMBER=1
AIRFLOW_CTX_DAG_RUN_ID=manual__2022-10-25T15:08:45.637429+00:00
[2022-10-25 15:08:53,424] {subprocess.py:62} INFO - Tmp dir root location: 
 /tmp
[2022-10-25 15:08:53,426] {subprocess.py:74} INFO - Running command: ['bash', '-c', 'cd /dbt && dbt seed --profiles-dir .']
[2022-10-25 15:08:53,445] {subprocess.py:85} INFO - Output:
[2022-10-25 15:08:53,473] {subprocess.py:92} INFO - bash: line 1: dbt: command not found
[2022-10-25 15:08:53,474] {subprocess.py:96} INFO - Command exited with return code 127
[2022-10-25 15:08:53,522] {taskinstance.py:1889} ERROR - Task failed with exception
Traceback (most recent call last):
  File "/home/airflow/.local/lib/python3.7/site-packages/airflow/operators/bash.py", line 195, in execute
    f'Bash command failed. The command returned a non-zero exit code {result.exit_code}.'
airflow.exceptions.AirflowException: Bash command failed. The command returned a non-zero exit code 127.
[2022-10-25 15:08:53,541] {taskinstance.py:1400} INFO - Marking task as FAILED. dag_id=1_init_once_seed_data, task_id=load_seed_data_once, execution_date=20221025T150845, start_date=20221025T150852, end_date=20221025T150853
[2022-10-25 15:08:53,709] {standard_task_runner.py:97} ERROR - Failed to execute job 149 for task load_seed_data_once (Bash command failed. The command returned a non-zero exit code 127.; 386)
[2022-10-25 15:08:53,784] {local_task_job.py:156} INFO - Task exited with return code 1
[2022-10-25 15:08:54,024] {local_task_job.py:273} INFO - 0 downstream tasks scheduled from follow-on schedule check
